Search term:  Bills
Updated C:\projects\orph.in\jarjamorp.github.io\trending.html
Search term:  Bills
images generated C:\projects\orph.in\jarjamorp.github.io\trending\img_020240923_221617.webp C:\projects\orph.in\jarjamorp.github.io\trending\img_020240923_221617-tn.webp
Updated C:\projects\orph.in\jarjamorp.github.io\trending.html
Search term:  Fever vs Sun
image generated C:\projects\orph.in\jarjamorp.github.io\trending\img_020240925_235921.webp
Updated C:\projects\orph.in\jarjamorp.github.io\trending.html
Search term:  Maggie Smith
image generated C:\projects\orph.in\jarjamorp.github.io\trending\img_020240927_193402.webp
Updated C:\projects\orph.in\jarjamorp.github.io\trending.html
Search term:  Maggie Smith
Traceback (most recent call last):
  File "C:\Users\harra\AppData\Roaming\Python\Python310\site-packages\httpx\_transports\default.py", line 72, in map_httpcore_exceptions
    yield
  File "C:\Users\harra\AppData\Roaming\Python\Python310\site-packages\httpx\_transports\default.py", line 236, in handle_request
    resp = self._pool.handle_request(req)
  File "C:\Users\harra\AppData\Roaming\Python\Python310\site-packages\httpcore\_sync\connection_pool.py", line 216, in handle_request
    raise exc from None
  File "C:\Users\harra\AppData\Roaming\Python\Python310\site-packages\httpcore\_sync\connection_pool.py", line 196, in handle_request
    response = connection.handle_request(
  File "C:\Users\harra\AppData\Roaming\Python\Python310\site-packages\httpcore\_sync\connection.py", line 101, in handle_request
    return self._connection.handle_request(request)
  File "C:\Users\harra\AppData\Roaming\Python\Python310\site-packages\httpcore\_sync\http11.py", line 143, in handle_request
    raise exc
  File "C:\Users\harra\AppData\Roaming\Python\Python310\site-packages\httpcore\_sync\http11.py", line 113, in handle_request
    ) = self._receive_response_headers(**kwargs)
  File "C:\Users\harra\AppData\Roaming\Python\Python310\site-packages\httpcore\_sync\http11.py", line 186, in _receive_response_headers
    event = self._receive_event(timeout=timeout)
  File "C:\Users\harra\AppData\Roaming\Python\Python310\site-packages\httpcore\_sync\http11.py", line 224, in _receive_event
    data = self._network_stream.read(
  File "C:\Users\harra\AppData\Roaming\Python\Python310\site-packages\httpcore\_backends\sync.py", line 124, in read
    with map_exceptions(exc_map):
  File "C:\ProgramData\anaconda3\lib\contextlib.py", line 153, in __exit__
    self.gen.throw(typ, value, traceback)
  File "C:\Users\harra\AppData\Roaming\Python\Python310\site-packages\httpcore\_exceptions.py", line 14, in map_exceptions
    raise to_exc(exc) from exc
httpcore.ReadTimeout: The read operation timed out

The above exception was the direct cause of the following exception:

Traceback (most recent call last):
  File "C:\Users\harra\AppData\Roaming\Python\Python310\site-packages\openai\_base_client.py", line 981, in _request
    response = self._client.send(
  File "C:\Users\harra\AppData\Roaming\Python\Python310\site-packages\httpx\_client.py", line 926, in send
    response = self._send_handling_auth(
  File "C:\Users\harra\AppData\Roaming\Python\Python310\site-packages\httpx\_client.py", line 954, in _send_handling_auth
    response = self._send_handling_redirects(
  File "C:\Users\harra\AppData\Roaming\Python\Python310\site-packages\httpx\_client.py", line 991, in _send_handling_redirects
    response = self._send_single_request(request)
  File "C:\Users\harra\AppData\Roaming\Python\Python310\site-packages\httpx\_client.py", line 1027, in _send_single_request
    response = transport.handle_request(request)
  File "C:\Users\harra\AppData\Roaming\Python\Python310\site-packages\httpx\_transports\default.py", line 235, in handle_request
    with map_httpcore_exceptions():
  File "C:\ProgramData\anaconda3\lib\contextlib.py", line 153, in __exit__
    self.gen.throw(typ, value, traceback)
  File "C:\Users\harra\AppData\Roaming\Python\Python310\site-packages\httpx\_transports\default.py", line 89, in map_httpcore_exceptions
    raise mapped_exc(message) from exc
httpx.ReadTimeout: The read operation timed out

The above exception was the direct cause of the following exception:

Traceback (most recent call last):
  File "C:\projects\orph.in\jarjamorp.github.io\_python\trending.py", line 149, in <module>
    main()
  File "C:\projects\orph.in\jarjamorp.github.io\_python\trending.py", line 140, in main
    large_filename, thumb_filename = generate_image(prompt, os.path.join(TRENDING_PATH, image_filename))
  File "C:\projects\orph.in\jarjamorp.github.io\_python\trending.py", line 34, in generate_image
    response = client.images.generate(
  File "C:\Users\harra\AppData\Roaming\Python\Python310\site-packages\openai\resources\images.py", line 264, in generate
    return self._post(
  File "C:\Users\harra\AppData\Roaming\Python\Python310\site-packages\openai\_base_client.py", line 1268, in post
    return cast(ResponseT, self.request(cast_to, opts, stream=stream, stream_cls=stream_cls))
  File "C:\Users\harra\AppData\Roaming\Python\Python310\site-packages\openai\_base_client.py", line 945, in request
    return self._request(
  File "C:\Users\harra\AppData\Roaming\Python\Python310\site-packages\openai\_base_client.py", line 990, in _request
    return self._retry_request(
  File "C:\Users\harra\AppData\Roaming\Python\Python310\site-packages\openai\_base_client.py", line 1083, in _retry_request
    return self._request(
  File "C:\Users\harra\AppData\Roaming\Python\Python310\site-packages\openai\_base_client.py", line 1005, in _request
    return self._retry_request(
  File "C:\Users\harra\AppData\Roaming\Python\Python310\site-packages\openai\_base_client.py", line 1083, in _retry_request
    return self._request(
  File "C:\Users\harra\AppData\Roaming\Python\Python310\site-packages\openai\_base_client.py", line 1000, in _request
    raise APITimeoutError(request=request) from err
openai.APITimeoutError: Request timed out.
