Search term:  Bills
Updated C:\projects\orph.in\jarjamorp.github.io\trending.html
Search term:  Bills
images generated C:\projects\orph.in\jarjamorp.github.io\trending\img_020240923_221617.webp C:\projects\orph.in\jarjamorp.github.io\trending\img_020240923_221617-tn.webp
Updated C:\projects\orph.in\jarjamorp.github.io\trending.html
Search term:  Fever vs Sun
image generated C:\projects\orph.in\jarjamorp.github.io\trending\img_020240925_235921.webp
Updated C:\projects\orph.in\jarjamorp.github.io\trending.html
Search term:  Maggie Smith
image generated C:\projects\orph.in\jarjamorp.github.io\trending\img_020240927_193402.webp
Updated C:\projects\orph.in\jarjamorp.github.io\trending.html
Search term:  Maggie Smith
Traceback (most recent call last):
  File "C:\Users\harra\AppData\Roaming\Python\Python310\site-packages\httpx\_transports\default.py", line 72, in map_httpcore_exceptions
    yield
  File "C:\Users\harra\AppData\Roaming\Python\Python310\site-packages\httpx\_transports\default.py", line 236, in handle_request
    resp = self._pool.handle_request(req)
  File "C:\Users\harra\AppData\Roaming\Python\Python310\site-packages\httpcore\_sync\connection_pool.py", line 216, in handle_request
    raise exc from None
  File "C:\Users\harra\AppData\Roaming\Python\Python310\site-packages\httpcore\_sync\connection_pool.py", line 196, in handle_request
    response = connection.handle_request(
  File "C:\Users\harra\AppData\Roaming\Python\Python310\site-packages\httpcore\_sync\connection.py", line 101, in handle_request
    return self._connection.handle_request(request)
  File "C:\Users\harra\AppData\Roaming\Python\Python310\site-packages\httpcore\_sync\http11.py", line 143, in handle_request
    raise exc
  File "C:\Users\harra\AppData\Roaming\Python\Python310\site-packages\httpcore\_sync\http11.py", line 113, in handle_request
    ) = self._receive_response_headers(**kwargs)
  File "C:\Users\harra\AppData\Roaming\Python\Python310\site-packages\httpcore\_sync\http11.py", line 186, in _receive_response_headers
    event = self._receive_event(timeout=timeout)
  File "C:\Users\harra\AppData\Roaming\Python\Python310\site-packages\httpcore\_sync\http11.py", line 224, in _receive_event
    data = self._network_stream.read(
  File "C:\Users\harra\AppData\Roaming\Python\Python310\site-packages\httpcore\_backends\sync.py", line 124, in read
    with map_exceptions(exc_map):
  File "C:\ProgramData\anaconda3\lib\contextlib.py", line 153, in __exit__
    self.gen.throw(typ, value, traceback)
  File "C:\Users\harra\AppData\Roaming\Python\Python310\site-packages\httpcore\_exceptions.py", line 14, in map_exceptions
    raise to_exc(exc) from exc
httpcore.ReadTimeout: The read operation timed out

The above exception was the direct cause of the following exception:

Traceback (most recent call last):
  File "C:\Users\harra\AppData\Roaming\Python\Python310\site-packages\openai\_base_client.py", line 981, in _request
    response = self._client.send(
  File "C:\Users\harra\AppData\Roaming\Python\Python310\site-packages\httpx\_client.py", line 926, in send
    response = self._send_handling_auth(
  File "C:\Users\harra\AppData\Roaming\Python\Python310\site-packages\httpx\_client.py", line 954, in _send_handling_auth
    response = self._send_handling_redirects(
  File "C:\Users\harra\AppData\Roaming\Python\Python310\site-packages\httpx\_client.py", line 991, in _send_handling_redirects
    response = self._send_single_request(request)
  File "C:\Users\harra\AppData\Roaming\Python\Python310\site-packages\httpx\_client.py", line 1027, in _send_single_request
    response = transport.handle_request(request)
  File "C:\Users\harra\AppData\Roaming\Python\Python310\site-packages\httpx\_transports\default.py", line 235, in handle_request
    with map_httpcore_exceptions():
  File "C:\ProgramData\anaconda3\lib\contextlib.py", line 153, in __exit__
    self.gen.throw(typ, value, traceback)
  File "C:\Users\harra\AppData\Roaming\Python\Python310\site-packages\httpx\_transports\default.py", line 89, in map_httpcore_exceptions
    raise mapped_exc(message) from exc
httpx.ReadTimeout: The read operation timed out

The above exception was the direct cause of the following exception:

Traceback (most recent call last):
  File "C:\projects\orph.in\jarjamorp.github.io\_python\trending.py", line 149, in <module>
    main()
  File "C:\projects\orph.in\jarjamorp.github.io\_python\trending.py", line 140, in main
    large_filename, thumb_filename = generate_image(prompt, os.path.join(TRENDING_PATH, image_filename))
  File "C:\projects\orph.in\jarjamorp.github.io\_python\trending.py", line 34, in generate_image
    response = client.images.generate(
  File "C:\Users\harra\AppData\Roaming\Python\Python310\site-packages\openai\resources\images.py", line 264, in generate
    return self._post(
  File "C:\Users\harra\AppData\Roaming\Python\Python310\site-packages\openai\_base_client.py", line 1268, in post
    return cast(ResponseT, self.request(cast_to, opts, stream=stream, stream_cls=stream_cls))
  File "C:\Users\harra\AppData\Roaming\Python\Python310\site-packages\openai\_base_client.py", line 945, in request
    return self._request(
  File "C:\Users\harra\AppData\Roaming\Python\Python310\site-packages\openai\_base_client.py", line 990, in _request
    return self._retry_request(
  File "C:\Users\harra\AppData\Roaming\Python\Python310\site-packages\openai\_base_client.py", line 1083, in _retry_request
    return self._request(
  File "C:\Users\harra\AppData\Roaming\Python\Python310\site-packages\openai\_base_client.py", line 1005, in _request
    return self._retry_request(
  File "C:\Users\harra\AppData\Roaming\Python\Python310\site-packages\openai\_base_client.py", line 1083, in _retry_request
    return self._request(
  File "C:\Users\harra\AppData\Roaming\Python\Python310\site-packages\openai\_base_client.py", line 1000, in _request
    raise APITimeoutError(request=request) from err
openai.APITimeoutError: Request timed out.
Search term:  Colorado football
image generated C:\projects\orph.in\jarjamorp.github.io\trending\img_020240928_235916.webp
Updated C:\projects\orph.in\jarjamorp.github.io\trending.html
Search term:  Kris Kristofferson
image generated C:\projects\orph.in\jarjamorp.github.io\trending\img_020240930_030256.webp
Updated C:\projects\orph.in\jarjamorp.github.io\trending.html
Search term:  John Amos
image generated C:\projects\orph.in\jarjamorp.github.io\trending\img_020241001_203904.webp
Updated C:\projects\orph.in\jarjamorp.github.io\trending.html
Search term:  John Amos
image generated C:\projects\orph.in\jarjamorp.github.io\trending\img_020241001_235915.webp
Updated C:\projects\orph.in\jarjamorp.github.io\trending.html
Traceback (most recent call last):
  File "C:\ProgramData\anaconda3\lib\site-packages\urllib3\connection.py", line 174, in _new_conn
    conn = connection.create_connection(
  File "C:\ProgramData\anaconda3\lib\site-packages\urllib3\util\connection.py", line 72, in create_connection
    for res in socket.getaddrinfo(host, port, family, socket.SOCK_STREAM):
  File "C:\ProgramData\anaconda3\lib\socket.py", line 955, in getaddrinfo
    for res in _socket.getaddrinfo(host, port, family, type, proto, flags):
socket.gaierror: [Errno 11001] getaddrinfo failed

During handling of the above exception, another exception occurred:

Traceback (most recent call last):
  File "C:\ProgramData\anaconda3\lib\site-packages\urllib3\connectionpool.py", line 703, in urlopen
    httplib_response = self._make_request(
  File "C:\ProgramData\anaconda3\lib\site-packages\urllib3\connectionpool.py", line 386, in _make_request
    self._validate_conn(conn)
  File "C:\ProgramData\anaconda3\lib\site-packages\urllib3\connectionpool.py", line 1042, in _validate_conn
    conn.connect()
  File "C:\ProgramData\anaconda3\lib\site-packages\urllib3\connection.py", line 358, in connect
    self.sock = conn = self._new_conn()
  File "C:\ProgramData\anaconda3\lib\site-packages\urllib3\connection.py", line 186, in _new_conn
    raise NewConnectionError(
urllib3.exceptions.NewConnectionError: <urllib3.connection.HTTPSConnection object at 0x00000223D5D3D6C0>: Failed to establish a new connection: [Errno 11001] getaddrinfo failed

During handling of the above exception, another exception occurred:

Traceback (most recent call last):
  File "C:\ProgramData\anaconda3\lib\site-packages\requests\adapters.py", line 489, in send
    resp = conn.urlopen(
  File "C:\ProgramData\anaconda3\lib\site-packages\urllib3\connectionpool.py", line 787, in urlopen
    retries = retries.increment(
  File "C:\ProgramData\anaconda3\lib\site-packages\urllib3\util\retry.py", line 592, in increment
    raise MaxRetryError(_pool, url, error or ResponseError(cause))
urllib3.exceptions.MaxRetryError: HTTPSConnectionPool(host='trends.google.com', port=443): Max retries exceeded with url: /trends/explore/?geo=US (Caused by NewConnectionError('<urllib3.connection.HTTPSConnection object at 0x00000223D5D3D6C0>: Failed to establish a new connection: [Errno 11001] getaddrinfo failed'))

During handling of the above exception, another exception occurred:

Traceback (most recent call last):
  File "C:\projects\orph.in\jarjamorp.github.io\_python\trending.py", line 149, in <module>
    main()
  File "C:\projects\orph.in\jarjamorp.github.io\_python\trending.py", line 133, in main
    search_term = get_top_trending_search_term()
  File "C:\projects\orph.in\jarjamorp.github.io\_python\trending.py", line 27, in get_top_trending_search_term
    pytrends = TrendReq()
  File "C:\Users\harra\AppData\Roaming\Python\Python310\site-packages\pytrends\request.py", line 56, in __init__
    self.cookies = self.GetGoogleCookie()
  File "C:\Users\harra\AppData\Roaming\Python\Python310\site-packages\pytrends\request.py", line 88, in GetGoogleCookie
    return dict(filter(lambda i: i[0] == 'NID', requests.get(
  File "C:\ProgramData\anaconda3\lib\site-packages\requests\api.py", line 73, in get
    return request("get", url, params=params, **kwargs)
  File "C:\ProgramData\anaconda3\lib\site-packages\requests\api.py", line 59, in request
    return session.request(method=method, url=url, **kwargs)
  File "C:\ProgramData\anaconda3\lib\site-packages\requests\sessions.py", line 587, in request
    resp = self.send(prep, **send_kwargs)
  File "C:\ProgramData\anaconda3\lib\site-packages\requests\sessions.py", line 701, in send
    r = adapter.send(request, **kwargs)
  File "C:\ProgramData\anaconda3\lib\site-packages\requests\adapters.py", line 565, in send
    raise ConnectionError(e, request=request)
requests.exceptions.ConnectionError: HTTPSConnectionPool(host='trends.google.com', port=443): Max retries exceeded with url: /trends/explore/?geo=US (Caused by NewConnectionError('<urllib3.connection.HTTPSConnection object at 0x00000223D5D3D6C0>: Failed to establish a new connection: [Errno 11001] getaddrinfo failed'))
Search term:  Falcons
image generated C:\projects\orph.in\jarjamorp.github.io\trending\img_020241004_002217.webp
Updated C:\projects\orph.in\jarjamorp.github.io\trending.html
Search term:  Oregon football
image generated C:\projects\orph.in\jarjamorp.github.io\trending\img_020241004_235916.webp
Updated C:\projects\orph.in\jarjamorp.github.io\trending.html
Search term:  Alabama football
image generated C:\projects\orph.in\jarjamorp.github.io\trending\img_020241005_235916.webp
Updated C:\projects\orph.in\jarjamorp.github.io\trending.html
Traceback (most recent call last):
  File "C:\ProgramData\anaconda3\lib\site-packages\urllib3\connection.py", line 174, in _new_conn
    conn = connection.create_connection(
  File "C:\ProgramData\anaconda3\lib\site-packages\urllib3\util\connection.py", line 72, in create_connection
    for res in socket.getaddrinfo(host, port, family, socket.SOCK_STREAM):
  File "C:\ProgramData\anaconda3\lib\socket.py", line 955, in getaddrinfo
    for res in _socket.getaddrinfo(host, port, family, type, proto, flags):
socket.gaierror: [Errno 11001] getaddrinfo failed

During handling of the above exception, another exception occurred:

Traceback (most recent call last):
  File "C:\ProgramData\anaconda3\lib\site-packages\urllib3\connectionpool.py", line 703, in urlopen
    httplib_response = self._make_request(
  File "C:\ProgramData\anaconda3\lib\site-packages\urllib3\connectionpool.py", line 386, in _make_request
    self._validate_conn(conn)
  File "C:\ProgramData\anaconda3\lib\site-packages\urllib3\connectionpool.py", line 1042, in _validate_conn
    conn.connect()
  File "C:\ProgramData\anaconda3\lib\site-packages\urllib3\connection.py", line 358, in connect
    self.sock = conn = self._new_conn()
  File "C:\ProgramData\anaconda3\lib\site-packages\urllib3\connection.py", line 186, in _new_conn
    raise NewConnectionError(
urllib3.exceptions.NewConnectionError: <urllib3.connection.HTTPSConnection object at 0x0000024DE184D5D0>: Failed to establish a new connection: [Errno 11001] getaddrinfo failed

During handling of the above exception, another exception occurred:

Traceback (most recent call last):
  File "C:\ProgramData\anaconda3\lib\site-packages\requests\adapters.py", line 489, in send
    resp = conn.urlopen(
  File "C:\ProgramData\anaconda3\lib\site-packages\urllib3\connectionpool.py", line 787, in urlopen
    retries = retries.increment(
  File "C:\ProgramData\anaconda3\lib\site-packages\urllib3\util\retry.py", line 592, in increment
    raise MaxRetryError(_pool, url, error or ResponseError(cause))
urllib3.exceptions.MaxRetryError: HTTPSConnectionPool(host='trends.google.com', port=443): Max retries exceeded with url: /trends/explore/?geo=US (Caused by NewConnectionError('<urllib3.connection.HTTPSConnection object at 0x0000024DE184D5D0>: Failed to establish a new connection: [Errno 11001] getaddrinfo failed'))

During handling of the above exception, another exception occurred:

Traceback (most recent call last):
  File "C:\projects\orph.in\jarjamorp.github.io\_python\trending.py", line 148, in <module>
    main()
  File "C:\projects\orph.in\jarjamorp.github.io\_python\trending.py", line 132, in main
    search_term = get_top_trending_search_term()
  File "C:\projects\orph.in\jarjamorp.github.io\_python\trending.py", line 26, in get_top_trending_search_term
    pytrends = TrendReq()
  File "C:\Users\harra\AppData\Roaming\Python\Python310\site-packages\pytrends\request.py", line 56, in __init__
    self.cookies = self.GetGoogleCookie()
  File "C:\Users\harra\AppData\Roaming\Python\Python310\site-packages\pytrends\request.py", line 88, in GetGoogleCookie
    return dict(filter(lambda i: i[0] == 'NID', requests.get(
  File "C:\ProgramData\anaconda3\lib\site-packages\requests\api.py", line 73, in get
    return request("get", url, params=params, **kwargs)
  File "C:\ProgramData\anaconda3\lib\site-packages\requests\api.py", line 59, in request
    return session.request(method=method, url=url, **kwargs)
  File "C:\ProgramData\anaconda3\lib\site-packages\requests\sessions.py", line 587, in request
    resp = self.send(prep, **send_kwargs)
  File "C:\ProgramData\anaconda3\lib\site-packages\requests\sessions.py", line 701, in send
    r = adapter.send(request, **kwargs)
  File "C:\ProgramData\anaconda3\lib\site-packages\requests\adapters.py", line 565, in send
    raise ConnectionError(e, request=request)
requests.exceptions.ConnectionError: HTTPSConnectionPool(host='trends.google.com', port=443): Max retries exceeded with url: /trends/explore/?geo=US (Caused by NewConnectionError('<urllib3.connection.HTTPSConnection object at 0x0000024DE184D5D0>: Failed to establish a new connection: [Errno 11001] getaddrinfo failed'))
Search term:  Alabama football
image generated C:\projects\orph.in\jarjamorp.github.io\trending\img_020241012_220907.webp
Updated C:\projects\orph.in\jarjamorp.github.io\trending.html
Search term:  Alabama football
image generated C:\projects\orph.in\jarjamorp.github.io\trending\img_020241012_221459.webp
Updated C:\projects\orph.in\jarjamorp.github.io\trending.html
Search term:  Texas football
image generated C:\projects\orph.in\jarjamorp.github.io\trending\img_020241012_235920.webp
Updated C:\projects\orph.in\jarjamorp.github.io\trending.html
Search term:  Victoria Secret Fashion Show 2024
image generated C:\projects\orph.in\jarjamorp.github.io\trending\img_020241015_212153.webp
Updated C:\projects\orph.in\jarjamorp.github.io\trending.html
Search term:  Victoria Secret Fashion Show 2024
image generated C:\projects\orph.in\jarjamorp.github.io\trending\img_020241015_235921.webp
Updated C:\projects\orph.in\jarjamorp.github.io\trending.html
Search term:  Sinwar
image generated C:\projects\orph.in\jarjamorp.github.io\trending\img_020241017_120007.webp
Updated C:\projects\orph.in\jarjamorp.github.io\trending.html
Search term:  Subnautica 2
image generated C:\projects\orph.in\jarjamorp.github.io\trending\img_020241018_045415.webp
Updated C:\projects\orph.in\jarjamorp.github.io\trending.html
Search term:  Duke football
image generated C:\projects\orph.in\jarjamorp.github.io\trending\img_020241018_235933.webp
Updated C:\projects\orph.in\jarjamorp.github.io\trending.html
Search term:  Georgia vs Texas
image generated C:\projects\orph.in\jarjamorp.github.io\trending\img_020241019_235917.webp
Updated C:\projects\orph.in\jarjamorp.github.io\trending.html
Search term:  Ravens vs Buccaneers
image generated C:\projects\orph.in\jarjamorp.github.io\trending\img_020241021_210215.webp
Updated C:\projects\orph.in\jarjamorp.github.io\trending.html
Search term:  DeAndre Hopkins
image generated C:\projects\orph.in\jarjamorp.github.io\trending\img_020241023_191329.webp
Updated C:\projects\orph.in\jarjamorp.github.io\trending.html
Search term:  Menendez brothers
Traceback (most recent call last):
  File "C:\projects\orph.in\jarjamorp.github.io\_python\trending.py", line 148, in <module>
    main()
  File "C:\projects\orph.in\jarjamorp.github.io\_python\trending.py", line 139, in main
    large_filename, thumb_filename = generate_image(prompt, os.path.join(TRENDING_PATH, image_filename))
  File "C:\projects\orph.in\jarjamorp.github.io\_python\trending.py", line 33, in generate_image
    response = client.images.generate(
  File "C:\Users\harra\AppData\Roaming\Python\Python310\site-packages\openai\resources\images.py", line 264, in generate
    return self._post(
  File "C:\Users\harra\AppData\Roaming\Python\Python310\site-packages\openai\_base_client.py", line 1268, in post
    return cast(ResponseT, self.request(cast_to, opts, stream=stream, stream_cls=stream_cls))
  File "C:\Users\harra\AppData\Roaming\Python\Python310\site-packages\openai\_base_client.py", line 945, in request
    return self._request(
  File "C:\Users\harra\AppData\Roaming\Python\Python310\site-packages\openai\_base_client.py", line 1049, in _request
    raise self._make_status_error_from_response(err.response) from None
openai.BadRequestError: Error code: 400 - {'error': {'code': 'content_policy_violation', 'message': 'Your request was rejected as a result of our safety system. Your prompt may contain text that is not allowed by our safety system.', 'param': None, 'type': 'invalid_request_error'}}
Search term:  Menendez brothers
Traceback (most recent call last):
  File "C:\projects\orph.in\jarjamorp.github.io\_python\trending.py", line 148, in <module>
    main()
  File "C:\projects\orph.in\jarjamorp.github.io\_python\trending.py", line 139, in main
    large_filename, thumb_filename = generate_image(prompt, os.path.join(TRENDING_PATH, image_filename))
  File "C:\projects\orph.in\jarjamorp.github.io\_python\trending.py", line 33, in generate_image
    response = client.images.generate(
  File "C:\Users\harra\AppData\Roaming\Python\Python310\site-packages\openai\resources\images.py", line 264, in generate
    return self._post(
  File "C:\Users\harra\AppData\Roaming\Python\Python310\site-packages\openai\_base_client.py", line 1268, in post
    return cast(ResponseT, self.request(cast_to, opts, stream=stream, stream_cls=stream_cls))
  File "C:\Users\harra\AppData\Roaming\Python\Python310\site-packages\openai\_base_client.py", line 945, in request
    return self._request(
  File "C:\Users\harra\AppData\Roaming\Python\Python310\site-packages\openai\_base_client.py", line 1049, in _request
    raise self._make_status_error_from_response(err.response) from None
openai.BadRequestError: Error code: 400 - {'error': {'code': 'content_policy_violation', 'message': 'Your request was rejected as a result of our safety system. Your prompt may contain text that is not allowed by our safety system.', 'param': None, 'type': 'invalid_request_error'}}
Search term:  World Series
image generated C:\projects\orph.in\jarjamorp.github.io\trending\img_020241025_235916.webp
Updated C:\projects\orph.in\jarjamorp.github.io\trending.html
Search term:  Celtics
image generated C:\projects\orph.in\jarjamorp.github.io\trending\img_020241027_123039.webp
Updated C:\projects\orph.in\jarjamorp.github.io\trending.html
Search term:  Ballon d'Or 2024
image generated C:\projects\orph.in\jarjamorp.github.io\trending\img_020241028_190617.webp
Updated C:\projects\orph.in\jarjamorp.github.io\trending.html
Search term:  Teri Garr
image generated C:\projects\orph.in\jarjamorp.github.io\trending\img_020241029_211013.webp
Updated C:\projects\orph.in\jarjamorp.github.io\trending.html
Traceback (most recent call last):
  File "C:\ProgramData\anaconda3\lib\site-packages\urllib3\connection.py", line 174, in _new_conn
    conn = connection.create_connection(
  File "C:\ProgramData\anaconda3\lib\site-packages\urllib3\util\connection.py", line 72, in create_connection
    for res in socket.getaddrinfo(host, port, family, socket.SOCK_STREAM):
  File "C:\ProgramData\anaconda3\lib\socket.py", line 955, in getaddrinfo
    for res in _socket.getaddrinfo(host, port, family, type, proto, flags):
socket.gaierror: [Errno 11001] getaddrinfo failed

During handling of the above exception, another exception occurred:

Traceback (most recent call last):
  File "C:\ProgramData\anaconda3\lib\site-packages\urllib3\connectionpool.py", line 703, in urlopen
    httplib_response = self._make_request(
  File "C:\ProgramData\anaconda3\lib\site-packages\urllib3\connectionpool.py", line 386, in _make_request
    self._validate_conn(conn)
  File "C:\ProgramData\anaconda3\lib\site-packages\urllib3\connectionpool.py", line 1042, in _validate_conn
    conn.connect()
  File "C:\ProgramData\anaconda3\lib\site-packages\urllib3\connection.py", line 358, in connect
    self.sock = conn = self._new_conn()
  File "C:\ProgramData\anaconda3\lib\site-packages\urllib3\connection.py", line 186, in _new_conn
    raise NewConnectionError(
urllib3.exceptions.NewConnectionError: <urllib3.connection.HTTPSConnection object at 0x0000023D1717D5D0>: Failed to establish a new connection: [Errno 11001] getaddrinfo failed

During handling of the above exception, another exception occurred:

Traceback (most recent call last):
  File "C:\ProgramData\anaconda3\lib\site-packages\requests\adapters.py", line 489, in send
    resp = conn.urlopen(
  File "C:\ProgramData\anaconda3\lib\site-packages\urllib3\connectionpool.py", line 787, in urlopen
    retries = retries.increment(
  File "C:\ProgramData\anaconda3\lib\site-packages\urllib3\util\retry.py", line 592, in increment
    raise MaxRetryError(_pool, url, error or ResponseError(cause))
urllib3.exceptions.MaxRetryError: HTTPSConnectionPool(host='trends.google.com', port=443): Max retries exceeded with url: /trends/explore/?geo=US (Caused by NewConnectionError('<urllib3.connection.HTTPSConnection object at 0x0000023D1717D5D0>: Failed to establish a new connection: [Errno 11001] getaddrinfo failed'))

During handling of the above exception, another exception occurred:

Traceback (most recent call last):
  File "C:\projects\orph.in\jarjamorp.github.io\_python\trending.py", line 148, in <module>
    main()
  File "C:\projects\orph.in\jarjamorp.github.io\_python\trending.py", line 132, in main
    search_term = get_top_trending_search_term()
  File "C:\projects\orph.in\jarjamorp.github.io\_python\trending.py", line 26, in get_top_trending_search_term
    pytrends = TrendReq()
  File "C:\Users\harra\AppData\Roaming\Python\Python310\site-packages\pytrends\request.py", line 56, in __init__
    self.cookies = self.GetGoogleCookie()
  File "C:\Users\harra\AppData\Roaming\Python\Python310\site-packages\pytrends\request.py", line 88, in GetGoogleCookie
    return dict(filter(lambda i: i[0] == 'NID', requests.get(
  File "C:\ProgramData\anaconda3\lib\site-packages\requests\api.py", line 73, in get
    return request("get", url, params=params, **kwargs)
  File "C:\ProgramData\anaconda3\lib\site-packages\requests\api.py", line 59, in request
    return session.request(method=method, url=url, **kwargs)
  File "C:\ProgramData\anaconda3\lib\site-packages\requests\sessions.py", line 587, in request
    resp = self.send(prep, **send_kwargs)
  File "C:\ProgramData\anaconda3\lib\site-packages\requests\sessions.py", line 701, in send
    r = adapter.send(request, **kwargs)
  File "C:\ProgramData\anaconda3\lib\site-packages\requests\adapters.py", line 565, in send
    raise ConnectionError(e, request=request)
requests.exceptions.ConnectionError: HTTPSConnectionPool(host='trends.google.com', port=443): Max retries exceeded with url: /trends/explore/?geo=US (Caused by NewConnectionError('<urllib3.connection.HTTPSConnection object at 0x0000023D1717D5D0>: Failed to establish a new connection: [Errno 11001] getaddrinfo failed'))
Search term:  Halloween
image generated C:\projects\orph.in\jarjamorp.github.io\trending\img_020241030_235927.webp
Updated C:\projects\orph.in\jarjamorp.github.io\trending.html
Search term:  Jets
image generated C:\projects\orph.in\jarjamorp.github.io\trending\img_020241031_235914.webp
Updated C:\projects\orph.in\jarjamorp.github.io\trending.html
Traceback (most recent call last):
  File "C:\ProgramData\anaconda3\lib\site-packages\urllib3\connectionpool.py", line 703, in urlopen
    httplib_response = self._make_request(
  File "C:\ProgramData\anaconda3\lib\site-packages\urllib3\connectionpool.py", line 386, in _make_request
    self._validate_conn(conn)
  File "C:\ProgramData\anaconda3\lib\site-packages\urllib3\connectionpool.py", line 1042, in _validate_conn
    conn.connect()
  File "C:\ProgramData\anaconda3\lib\site-packages\urllib3\connection.py", line 414, in connect
    self.sock = ssl_wrap_socket(
  File "C:\ProgramData\anaconda3\lib\site-packages\urllib3\util\ssl_.py", line 449, in ssl_wrap_socket
    ssl_sock = _ssl_wrap_socket_impl(
  File "C:\ProgramData\anaconda3\lib\site-packages\urllib3\util\ssl_.py", line 493, in _ssl_wrap_socket_impl
    return ssl_context.wrap_socket(sock, server_hostname=server_hostname)
  File "C:\ProgramData\anaconda3\lib\ssl.py", line 513, in wrap_socket
    return self.sslsocket_class._create(
  File "C:\ProgramData\anaconda3\lib\ssl.py", line 1071, in _create
    self.do_handshake()
  File "C:\ProgramData\anaconda3\lib\ssl.py", line 1342, in do_handshake
    self._sslobj.do_handshake()
ConnectionAbortedError: [WinError 10053] An established connection was aborted by the software in your host machine

During handling of the above exception, another exception occurred:

Traceback (most recent call last):
  File "C:\ProgramData\anaconda3\lib\site-packages\requests\adapters.py", line 489, in send
    resp = conn.urlopen(
  File "C:\ProgramData\anaconda3\lib\site-packages\urllib3\connectionpool.py", line 787, in urlopen
    retries = retries.increment(
  File "C:\ProgramData\anaconda3\lib\site-packages\urllib3\util\retry.py", line 550, in increment
    raise six.reraise(type(error), error, _stacktrace)
  File "C:\ProgramData\anaconda3\lib\site-packages\urllib3\packages\six.py", line 769, in reraise
    raise value.with_traceback(tb)
  File "C:\ProgramData\anaconda3\lib\site-packages\urllib3\connectionpool.py", line 703, in urlopen
    httplib_response = self._make_request(
  File "C:\ProgramData\anaconda3\lib\site-packages\urllib3\connectionpool.py", line 386, in _make_request
    self._validate_conn(conn)
  File "C:\ProgramData\anaconda3\lib\site-packages\urllib3\connectionpool.py", line 1042, in _validate_conn
    conn.connect()
  File "C:\ProgramData\anaconda3\lib\site-packages\urllib3\connection.py", line 414, in connect
    self.sock = ssl_wrap_socket(
  File "C:\ProgramData\anaconda3\lib\site-packages\urllib3\util\ssl_.py", line 449, in ssl_wrap_socket
    ssl_sock = _ssl_wrap_socket_impl(
  File "C:\ProgramData\anaconda3\lib\site-packages\urllib3\util\ssl_.py", line 493, in _ssl_wrap_socket_impl
    return ssl_context.wrap_socket(sock, server_hostname=server_hostname)
  File "C:\ProgramData\anaconda3\lib\ssl.py", line 513, in wrap_socket
    return self.sslsocket_class._create(
  File "C:\ProgramData\anaconda3\lib\ssl.py", line 1071, in _create
    self.do_handshake()
  File "C:\ProgramData\anaconda3\lib\ssl.py", line 1342, in do_handshake
    self._sslobj.do_handshake()
urllib3.exceptions.ProtocolError: ('Connection aborted.', ConnectionAbortedError(10053, 'An established connection was aborted by the software in your host machine', None, 10053, None))

During handling of the above exception, another exception occurred:

Traceback (most recent call last):
  File "C:\projects\orph.in\jarjamorp.github.io\_python\trending.py", line 148, in <module>
    main()
  File "C:\projects\orph.in\jarjamorp.github.io\_python\trending.py", line 132, in main
    search_term = get_top_trending_search_term()
  File "C:\projects\orph.in\jarjamorp.github.io\_python\trending.py", line 26, in get_top_trending_search_term
    pytrends = TrendReq()
  File "C:\Users\harra\AppData\Roaming\Python\Python310\site-packages\pytrends\request.py", line 56, in __init__
    self.cookies = self.GetGoogleCookie()
  File "C:\Users\harra\AppData\Roaming\Python\Python310\site-packages\pytrends\request.py", line 88, in GetGoogleCookie
    return dict(filter(lambda i: i[0] == 'NID', requests.get(
  File "C:\ProgramData\anaconda3\lib\site-packages\requests\api.py", line 73, in get
    return request("get", url, params=params, **kwargs)
  File "C:\ProgramData\anaconda3\lib\site-packages\requests\api.py", line 59, in request
    return session.request(method=method, url=url, **kwargs)
  File "C:\ProgramData\anaconda3\lib\site-packages\requests\sessions.py", line 587, in request
    resp = self.send(prep, **send_kwargs)
  File "C:\ProgramData\anaconda3\lib\site-packages\requests\sessions.py", line 701, in send
    r = adapter.send(request, **kwargs)
  File "C:\ProgramData\anaconda3\lib\site-packages\requests\adapters.py", line 547, in send
    raise ConnectionError(err, request=request)
requests.exceptions.ConnectionError: ('Connection aborted.', ConnectionAbortedError(10053, 'An established connection was aborted by the software in your host machine', None, 10053, None))
Search term:  Penn State football
image generated C:\projects\orph.in\jarjamorp.github.io\trending\img_020241102_235919.webp
Updated C:\projects\orph.in\jarjamorp.github.io\trending.html
Search term:  Quincy Jones
image generated C:\projects\orph.in\jarjamorp.github.io\trending\img_020241104_030637.webp
Updated C:\projects\orph.in\jarjamorp.github.io\trending.html
Search term:  Robert Kennedy
Traceback (most recent call last):
  File "C:\projects\orph.in\jarjamorp.github.io\_python\trending.py", line 148, in <module>
    main()
  File "C:\projects\orph.in\jarjamorp.github.io\_python\trending.py", line 139, in main
    large_filename, thumb_filename = generate_image(prompt, os.path.join(TRENDING_PATH, image_filename))
  File "C:\projects\orph.in\jarjamorp.github.io\_python\trending.py", line 33, in generate_image
    response = client.images.generate(
  File "C:\Users\harra\AppData\Roaming\Python\Python310\site-packages\openai\resources\images.py", line 264, in generate
    return self._post(
  File "C:\Users\harra\AppData\Roaming\Python\Python310\site-packages\openai\_base_client.py", line 1268, in post
    return cast(ResponseT, self.request(cast_to, opts, stream=stream, stream_cls=stream_cls))
  File "C:\Users\harra\AppData\Roaming\Python\Python310\site-packages\openai\_base_client.py", line 945, in request
    return self._request(
  File "C:\Users\harra\AppData\Roaming\Python\Python310\site-packages\openai\_base_client.py", line 1049, in _request
    raise self._make_status_error_from_response(err.response) from None
openai.BadRequestError: Error code: 400 - {'error': {'code': 'content_policy_violation', 'message': 'Your request was rejected as a result of our safety system. Your prompt may contain text that is not allowed by our safety system.', 'param': None, 'type': 'invalid_request_error'}}
Search term:  Bitcoin price
image generated C:\projects\orph.in\jarjamorp.github.io\trending\img_020241106_114056.webp
Updated C:\projects\orph.in\jarjamorp.github.io\trending.html
Search term:  Stock market today
Traceback (most recent call last):
  File "C:\Users\harra\AppData\Roaming\Python\Python310\site-packages\httpx\_transports\default.py", line 72, in map_httpcore_exceptions
    yield
  File "C:\Users\harra\AppData\Roaming\Python\Python310\site-packages\httpx\_transports\default.py", line 236, in handle_request
    resp = self._pool.handle_request(req)
  File "C:\Users\harra\AppData\Roaming\Python\Python310\site-packages\httpcore\_sync\connection_pool.py", line 216, in handle_request
    raise exc from None
  File "C:\Users\harra\AppData\Roaming\Python\Python310\site-packages\httpcore\_sync\connection_pool.py", line 196, in handle_request
    response = connection.handle_request(
  File "C:\Users\harra\AppData\Roaming\Python\Python310\site-packages\httpcore\_sync\connection.py", line 101, in handle_request
    return self._connection.handle_request(request)
  File "C:\Users\harra\AppData\Roaming\Python\Python310\site-packages\httpcore\_sync\http11.py", line 143, in handle_request
    raise exc
  File "C:\Users\harra\AppData\Roaming\Python\Python310\site-packages\httpcore\_sync\http11.py", line 113, in handle_request
    ) = self._receive_response_headers(**kwargs)
  File "C:\Users\harra\AppData\Roaming\Python\Python310\site-packages\httpcore\_sync\http11.py", line 186, in _receive_response_headers
    event = self._receive_event(timeout=timeout)
  File "C:\Users\harra\AppData\Roaming\Python\Python310\site-packages\httpcore\_sync\http11.py", line 224, in _receive_event
    data = self._network_stream.read(
  File "C:\Users\harra\AppData\Roaming\Python\Python310\site-packages\httpcore\_backends\sync.py", line 124, in read
    with map_exceptions(exc_map):
  File "C:\ProgramData\anaconda3\lib\contextlib.py", line 153, in __exit__
    self.gen.throw(typ, value, traceback)
  File "C:\Users\harra\AppData\Roaming\Python\Python310\site-packages\httpcore\_exceptions.py", line 14, in map_exceptions
    raise to_exc(exc) from exc
httpcore.ReadTimeout: The read operation timed out

The above exception was the direct cause of the following exception:

Traceback (most recent call last):
  File "C:\Users\harra\AppData\Roaming\Python\Python310\site-packages\openai\_base_client.py", line 981, in _request
    response = self._client.send(
  File "C:\Users\harra\AppData\Roaming\Python\Python310\site-packages\httpx\_client.py", line 926, in send
    response = self._send_handling_auth(
  File "C:\Users\harra\AppData\Roaming\Python\Python310\site-packages\httpx\_client.py", line 954, in _send_handling_auth
    response = self._send_handling_redirects(
  File "C:\Users\harra\AppData\Roaming\Python\Python310\site-packages\httpx\_client.py", line 991, in _send_handling_redirects
    response = self._send_single_request(request)
  File "C:\Users\harra\AppData\Roaming\Python\Python310\site-packages\httpx\_client.py", line 1027, in _send_single_request
    response = transport.handle_request(request)
  File "C:\Users\harra\AppData\Roaming\Python\Python310\site-packages\httpx\_transports\default.py", line 235, in handle_request
    with map_httpcore_exceptions():
  File "C:\ProgramData\anaconda3\lib\contextlib.py", line 153, in __exit__
    self.gen.throw(typ, value, traceback)
  File "C:\Users\harra\AppData\Roaming\Python\Python310\site-packages\httpx\_transports\default.py", line 89, in map_httpcore_exceptions
    raise mapped_exc(message) from exc
httpx.ReadTimeout: The read operation timed out

The above exception was the direct cause of the following exception:

Traceback (most recent call last):
  File "C:\projects\orph.in\jarjamorp.github.io\_python\trending.py", line 148, in <module>
    main()
  File "C:\projects\orph.in\jarjamorp.github.io\_python\trending.py", line 139, in main
    large_filename, thumb_filename = generate_image(prompt, os.path.join(TRENDING_PATH, image_filename))
  File "C:\projects\orph.in\jarjamorp.github.io\_python\trending.py", line 33, in generate_image
    response = client.images.generate(
  File "C:\Users\harra\AppData\Roaming\Python\Python310\site-packages\openai\resources\images.py", line 264, in generate
    return self._post(
  File "C:\Users\harra\AppData\Roaming\Python\Python310\site-packages\openai\_base_client.py", line 1268, in post
    return cast(ResponseT, self.request(cast_to, opts, stream=stream, stream_cls=stream_cls))
  File "C:\Users\harra\AppData\Roaming\Python\Python310\site-packages\openai\_base_client.py", line 945, in request
    return self._request(
  File "C:\Users\harra\AppData\Roaming\Python\Python310\site-packages\openai\_base_client.py", line 990, in _request
    return self._retry_request(
  File "C:\Users\harra\AppData\Roaming\Python\Python310\site-packages\openai\_base_client.py", line 1083, in _retry_request
    return self._request(
  File "C:\Users\harra\AppData\Roaming\Python\Python310\site-packages\openai\_base_client.py", line 1005, in _request
    return self._retry_request(
  File "C:\Users\harra\AppData\Roaming\Python\Python310\site-packages\openai\_base_client.py", line 1083, in _retry_request
    return self._request(
  File "C:\Users\harra\AppData\Roaming\Python\Python310\site-packages\openai\_base_client.py", line 1000, in _request
    raise APITimeoutError(request=request) from err
openai.APITimeoutError: Request timed out.
